<?xml version="1.0" encoding="utf-8"?>
<!-- This URDF was automatically created by SolidWorks to URDF Exporter! Originally created by Stephen Brawner (brawner@gmail.com) 
     Commit Version: 1.6.0-4-g7f85cfe  Build Version: 1.6.7995.38578
     For more information, please see http://wiki.ros.org/sw_urdf_exporter -->
<robot
  name="robot_description"  xmlns:xacro="http://ros.org/wiki/xacro">
  <xacro:include filename="$(find robot_description)/urdf/robot_description.gazebo.xacro" /> 
  <link name="base_footprint">
  </link>
  
  <joint name="base_joint" type="fixed">
    <parent link="base_footprint"/>
    <child link="base_link"/>
    <origin xyz="0.0 0.0 0.0" rpy="0 0 0"/>
  </joint>

  <link
    name="base_link">
    <inertial>
      <origin
        xyz="2.6246E-14 2.3582E-14 -0.0015"
        rpy="0 0 0" />
      <mass
        value="0.039002" />
      <inertia
        ixx="3.2716E-05"
        ixy="-2.1462E-13"
        ixz="-2.6892E-20"
        iyy="6.7767E-05"
        iyz="1.2263E-20"
        izz="0.00010042" />
    </inertial>
    <visual>
      <origin
        xyz="0 0 0"
        rpy="0 0 0" />
      <geometry>
        <mesh
          filename="package://robot_description/meshes/base_link.STL" />
      </geometry>
      <material
        name="">
        <color
          rgba="0.79216 0.81961 0.93333 1" />
      </material>
    </visual>
    <collision>
      <origin
        xyz="0 0 0"
        rpy="0 0 0" />
      <geometry>
        <mesh
          filename="package://robot_description/meshes/base_link.STL" />
      </geometry>
    </collision>
  </link>
  <link
    name="wheel_left_Link">
    <inertial>
      <origin
        xyz="3.2081E-06 -0.027055 0.00013509"
        rpy="0 0 0" />
      <mass
        value="0.035371" />
      <inertia
        ixx="7.2964E-06"
        ixy="-1.2651E-09"
        ixz="-6.992E-11"
        iyy="7.5055E-06"
        iyz="1.0517E-07"
        izz="7.2459E-06" />
    </inertial>
    <visual>
      <origin
        xyz="0 0 0"
        rpy="0 0 0" />
      <geometry>
        <mesh
          filename="package://robot_description/meshes/wheel_left_Link.STL" />
      </geometry>
      <material
        name="">
        <color
          rgba="0.79216 0.81961 0.93333 1" />
      </material>
    </visual>
    <collision>
      <origin
        xyz="0 0 0"
        rpy="0 0 0" />
      <geometry>
        <mesh
          filename="package://robot_description/meshes/wheel_left_Link.STL" />
      </geometry>
    </collision>
  </link>
  <joint
    name="wheel_left_joint"
    type="continuous">
    <origin
      xyz="-0.048791 0.0715 -0.023"
      rpy="0 0 0" />
    <parent
      link="base_link" />
    <child
      link="wheel_left_Link" />
    <axis
      xyz="0 1 0" />
  </joint>
  <link
    name="wheel_right_Link">
    <inertial>
      <origin
        xyz="-3.2081E-06 0.027055 0.00013509"
        rpy="0 0 0" />
      <mass
        value="0.035371" />
      <inertia
        ixx="7.2964E-06"
        ixy="-1.2651E-09"
        ixz="6.992E-11"
        iyy="7.5055E-06"
        iyz="-1.0517E-07"
        izz="7.2459E-06" />
    </inertial>
    <visual>
      <origin
        xyz="0 0 0"
        rpy="0 0 0" />
      <geometry>
        <mesh
          filename="package://robot_description/meshes/wheel_right_Link.STL" />
      </geometry>
      <material
        name="">
        <color
          rgba="0.79216 0.81961 0.93333 1" />
      </material>
    </visual>
    <collision>
      <origin
        xyz="0 0 0"
        rpy="0 0 0" />
      <geometry>
        <mesh
          filename="package://robot_description/meshes/wheel_right_Link.STL" />
      </geometry>
    </collision>
  </link>
  <joint
    name="wheel_right_joint"
    type="continuous">
    <origin
      xyz="-0.048791 -0.0715 -0.023"
      rpy="0 0 0" />
    <parent
      link="base_link" />
    <child
      link="wheel_right_Link" />
    <axis
      xyz="0 1 0" />
  </joint>
  <link
    name="wheel_universal_Link">
    <inertial>
      <origin
        xyz="-0.0049043 0.0072459 0.0084569"
        rpy="0 0 0" />
      <mass
        value="0.010932" />
      <inertia
        ixx="1.9746E-06"
        ixy="1.5756E-10"
        ixz="7.6294E-07"
        iyy="2.4635E-06"
        iyz="-2.4689E-10"
        izz="1.3438E-06" />
    </inertial>
    <visual>
      <origin
        xyz="0 0 0"
        rpy="0 0 0" />
      <geometry>
        <mesh
          filename="package://robot_description/meshes/wheel_universal_Link.STL" />
      </geometry>
      <material
        name="">
        <color
          rgba="0.74118 0.90196 0.95686 1" />
      </material>
    </visual>
    <collision>
      <origin
        xyz="0 0 0"
        rpy="0 0 0" />
      <geometry>
        <mesh
          filename="package://robot_description/meshes/wheel_universal_Link.STL" />
      </geometry>
    </collision>
  </link>
  <joint
    name="wheel_universal_joint"
    type="fixed">
    <origin
      xyz="0.063633 -0.0072487 -0.034"
      rpy="0 0 0" />
    <parent
      link="base_link" />
    <child
      link="wheel_universal_Link" />
    <axis
      xyz="0 0 0" />
  </joint>
  <link
    name="laser_Link">
    <inertial>
      <origin
        xyz="-0.0030189 -0.00020139 -0.019649"
        rpy="0 0 0" />
      <mass
        value="0.094023" />
      <inertia
        ixx="3.4259E-05"
        ixy="-1.2348E-09"
        ixz="-2.1308E-07"
        iyy="5.7727E-05"
        iyz="-8.9097E-10"
        izz="7.5176E-05" />
    </inertial>
    <visual>
      <origin
        xyz="0 0 0"
        rpy="0 0 0" />
      <geometry>
        <mesh
          filename="package://robot_description/meshes/laser_Link.STL" />
      </geometry>
      <material
        name="">
        <color
          rgba="0.37255 0.55686 1 1" />
      </material>
    </visual>
    <collision>
      <origin
        xyz="0 0 0"
        rpy="0 0 0" />
      <geometry>
        <mesh
          filename="package://robot_description/meshes/laser_Link.STL" />
      </geometry>
    </collision>
  </link>
  <joint
    name="laser_joint"
    type="fixed">
    <origin
      xyz="-0.0064435 0.002216 0.078664"
      rpy="0 0 3.1416" />
    <parent
      link="base_link" />
    <child
      link="laser_Link" />
    <axis
      xyz="0 0 0" />
  </joint>
  <link
    name="imu_Link">
    <inertial>
      <origin
        xyz="-0.021463 0.017572 -0.010408"
        rpy="0 0 0" />
      <mass
        value="0.017226" />
      <inertia
        ixx="2.2162E-06"
        ixy="3.6168E-10"
        ixz="-1.8429E-08"
        iyy="4.9944E-06"
        iyz="3.6637E-11"
        izz="7.034E-06" />
    </inertial>
    <visual>
      <origin
        xyz="0 0 0"
        rpy="0 0 0" />
      <geometry>
        <mesh
          filename="package://robot_description/meshes/imu_Link.STL" />
      </geometry>
      <material
        name="">
        <color
          rgba="1 1 1 1" />
      </material>
    </visual>
    <collision>
      <origin
        xyz="0 0 0"
        rpy="0 0 0" />
      <geometry>
        <mesh
          filename="package://robot_description/meshes/imu_Link.STL" />
      </geometry>
    </collision>
  </link>
  <joint
    name="imu_joint"
    type="fixed">
    <origin
      xyz="0.037033 -0.018447 0.013909"
      rpy="0 0 0" />
    <parent
      link="base_link" />
    <child
      link="imu_Link" />
    <axis
      xyz="0 0 0" />
  </joint>

    <!-- camera -->
  <link name="camera_link">  
    <visual>  
      <geometry>  
        <box size="0.01 0.01 0.01"/>  
      </geometry>  
      <material name="white">  
          <color rgba="1 1 1 1"/>  
      </material>  
    </visual>  
  </link>  

  <joint name="camera_joint" type="fixed">  
    <parent link="base_link"/>  
    <child link="camera_link"/>  
    <origin xyz="0.04 0 0.025"/>  
  </joint> 
</robot>